Workbook

Sheet ①はじめに
B2: チェックリスト — 「思い出カメラ」反応テスト
B4: ・このファイルはテストの記録用です。オペレーターが記入します。
B5: ・記入するのはシート②〜④だけ。⑤は自動集計なので見るだけです。
B6: ・記入例（グレーの行）を参考にしてください。
B8: 組み合わせ（ペアリング）表
B9: Day2（セッション1）: 高齢者役＝テスターA／家族役＝テスターB
B10: Day3（セッション2）: 高齢者役＝テスターB／家族役＝テスターC
B11: Day4（セッション3）: 高齢者役＝テスターC／家族役＝テスターA

Sheet ②準備チェック
A1: チェックリスト — 準備チェック（毎回の通話前）
A3: チェック項目 | B3: Round1-Day2 | C3: Round1-Day3 | D3: Round1-Day4 | E3: Round2-Day2 | F3: Round2-Day3 | G3: Round2-Day4
A4: 【家族役】家族側ページに Googleでサインインできた
A5: 【家族役】画面左下に「📊ログ」ボタンが見える
A6: 【高齢者役】顔が画面に映っている（距離50cmくらい）
A7: 【高齢者役】部屋が静か（テレビ消灯）
A8: 【家族役】画面録画を開始した
A9: 【オペレーター】このチェックリストを開いた
A10: 【高齢者役】ノイズゲートをOFFにした（PC本体・イヤホン/マイクの両方。ノイキャンとは別機能）
A11: ※ 空欄=未確認。プルダウンから「✓」を選んでください。

Sheet ③実施記録
A1: チェックリスト — 実施記録（メイン） | J1: セッション１ | K1: 高齢者側 | L1: テスターC
J2: セッション２ | K2: 高齢者側 | L2: テスターB
A3: ラウンド | B3: セッション(Day) | C3: 番号 | D3: 場面 | E3: 正解 | F3: 実施日 | G3: 反応した回数 | H3: 期待どおり？ | I3: メモ | J3: 高齢者役_環境 | K3: 高齢者役_マイク | L3: 家族役_環境 | M3: 家族役_マイク
A4: 例 | B4: 1 | C4: A1 | D4: 静かにする | E4: 反応しない | F4: 7/15 | G4: 0 | H4: ◯ | I4: 問題なし | J4: {=IFERROR(INDEX('④回収ファイル一覧'!$G$4:$G$11,MATCH(A4&"-"&B4,'④回収ファイル一覧'!$K$4:$K$11,0)),"")} | K4: {=IFERROR(INDEX('④回収ファイル一覧'!$H$4:$H$11,MATCH(A4&"-"&B4,'④回収ファイル一覧'!$K$4:$K$11,0)),"")} | L4: {=IFERROR(INDEX('④回収ファイル一覧'!$I$4:$I$11,MATCH(A4&"-"&B4,'④回収ファイル一覧'!$K$4:$K$11,0)),"")} | M4: {=IFERROR(INDEX('④回収ファイル一覧'!$J$4:$J$11,MATCH(A4&"-"&B4,'④回収ファイル一覧'!$K$4:$K$11,0)),"")}
A5: 1 | B5: 1 | C5: A1 | D5: 静かにする | E5: 反応しない | F5: 46215 | G5: 1 | H5: × | I5: 機械音みたいなものに反応 | J5: {=IFERROR(INDEX('④回収ファイル一覧'!$G$4:$G$11,MATCH(A5&"-"&B5,'④回収ファイル一覧'!$K$4:$K$11,0)),"")} | K5: {=IFERROR(INDEX('④回収ファイル一覧'!$H$4:$H$11,MATCH(A5&"-"&B5,'④回収ファイル一覧'!$K$4:$K$11,0)),"")} | L5: {=IFERROR(INDEX('④回収ファイル一覧'!$I$4:$I$11,MATCH(A5&"-"&B5,'④回収ファイル一覧'!$K$4:$K$11,0)),"")} | M5: {=IFERROR(INDEX('④回収ファイル一覧'!$J$4:$J$11,MATCH(A5&"-"&B5,'④回収ファイル一覧'!$K$4:$K$11,0)),"")}
A6: 1 | B6: 1 | C6: A2 | D6: ふつうの雑談（2分） | E6: 反応しない | F6: 46215 | G6: 9 | H6: × | I6: 平坦な声で世間話をしているが9回も反応した | J6: {=IFERROR(INDEX('④回収ファイル一覧'!$G$4:$G$11,MATCH(A6&"-"&B6,'④回収ファイル一覧'!$K$4:$K$11,0)),"")} | K6: {=IFERROR(INDEX('④回収ファイル一覧'!$H$4:$H$11,MATCH(A6&"-"&B6,'④回収ファイル一覧'!$K$4:$K$11,0)),"")} | L6: {=IFERROR(INDEX('④回収ファイル一覧'!$I$4:$I$11,MATCH(A6&"-"&B6,'④回収ファイル一覧'!$K$4:$K$11,0)),"")} | M6: {=IFERROR(INDEX('④回収ファイル一覧'!$J$4:$J$11,MATCH(A6&"-"&B6,'④回収ファイル一覧'!$K$4:$K$11,0)),"")}
A7: 1 | B7: 1 | C7: A3 | D7: 本を読む | E7: 反応しない | F7: 46215 | G7: 14 | H7: × | J7: {=IFERROR(INDEX('④回収ファイル一覧'!$G$4:$G$11,MATCH(A7&"-"&B7,'④回収ファイル一覧'!$K$4:$K$11,0)),"")} | K7: {=IFERROR(INDEX('④回収ファイル一覧'!$H$4:$H$11,MATCH(A7&"-"&B7,'④回収ファイル一覧'!$K$4:$K$11,0)),"")} | L7: {=IFERROR(INDEX('④回収ファイル一覧'!$I$4:$I$11,MATCH(A7&"-"&B7,'④回収ファイル一覧'!$K$4:$K$11,0)),"")} | M7: {=IFERROR(INDEX('④回収ファイル一覧'!$J$4:$J$11,MATCH(A7&"-"&B7,'④回収ファイル一覧'!$K$4:$K$11,0)),"")}
A8: 1 | B8: 1 | C8: A4 | D8: 生活音を出す | E8: 反応しない | F8: 46215 | G8: 5 | H8: × | I8: 掃除機の音、ペットボトルに水を入れる音、 | J8: {=IFERROR(INDEX('④回収ファイル一覧'!$G$4:$G$11,MATCH(A8&"-"&B8,'④回収ファイル一覧'!$K$4:$K$11,0)),"")} | K8: {=IFERROR(INDEX('④回収ファイル一覧'!$H$4:$H$11,MATCH(A8&"-"&B8,'④回収ファイル一覧'!$K$4:$K$11,0)),"")} | L8: {=IFERROR(INDEX('④回収ファイル一覧'!$I$4:$I$11,MATCH(A8&"-"&B8,'④回収ファイル一覧'!$K$4:$K$11,0)),"")} | M8: {=IFERROR(INDEX('④回収ファイル一覧'!$J$4:$J$11,MATCH(A8&"-"&B8,'④回収ファイル一覧'!$K$4:$K$11,0)),"")}
A9: 1 | B9: 1 | C9: A5 | D9: 最初のあいさつ（かけ直し） | E9: 反応しない | F9: 46215 | G9: 1 | H9: × | J9: {=IFERROR(INDEX('④回収ファイル一覧'!$G$4:$G$11,MATCH(A9&"-"&B9,'④回収ファイル一覧'!$K$4:$K$11,0)),"")} | K9: {=IFERROR(INDEX('④回収ファイル一覧'!$H$4:$H$11,MATCH(A9&"-"&B9,'④回収ファイル一覧'!$K$4:$K$11,0)),"")} | L9: {=IFERROR(INDEX('④回収ファイル一覧'!$I$4:$I$11,MATCH(A9&"-"&B9,'④回収ファイル一覧'!$K$4:$K$11,0)),"")} | M9: {=IFERROR(INDEX('④回収ファイル一覧'!$J$4:$J$11,MATCH(A9&"-"&B9,'④回収ファイル一覧'!$K$4:$K$11,0)),"")}
A10: 1 | B10: 1 | C10: A6 | D10: 立って戻る | E10: 反応しない | F10: 46215 | G10: 8 | H10: × | I10: 途中で落ちたので3回目のログに入っている | J10: {=IFERROR(INDEX('④回収ファイル一覧'!$G$4:$G$11,MATCH(A10&"-"&B10,'④回収ファイル一覧'!$K$4:$K$11,0)),"")} | K10: {=IFERROR(INDEX('④回収ファイル一覧'!$H$4:$H$11,MATCH(A10&"-"&B10,'④回収ファイル一覧'!$K$4:$K$11,0)),"")} | L10: {=IFERROR(INDEX('④回収ファイル一覧'!$I$4:$I$11,MATCH(A10&"-"&B10,'④回収ファイル一覧'!$K$4:$K$11,0)),"")} | M10: {=IFERROR(INDEX('④回収ファイル一覧'!$J$4:$J$11,MATCH(A10&"-"&B10,'④回収ファイル一覧'!$K$4:$K$11,0)),"")}
A11: 1 | B11: 1 | C11: B1 | D11: 声を出して笑う | E11: 反応する | F11: 46215 | G11: 5 | H11: ◯ | J11: {=IFERROR(INDEX('④回収ファイル一覧'!$G$4:$G$11,MATCH(A11&"-"&B11,'④回収ファイル一覧'!$K$4:$K$11,0)),"")} | K11: {=IFERROR(INDEX('④回収ファイル一覧'!$H$4:$H$11,MATCH(A11&"-"&B11,'④回収ファイル一覧'!$K$4:$K$11,0)),"")} | L11: {=IFERROR(INDEX('④回収ファイル一覧'!$I$4:$I$11,MATCH(A11&"-"&B11,'④回収ファイル一覧'!$K$4:$K$11,0)),"")} | M11: {=IFERROR(INDEX('④回収ファイル一覧'!$J$4:$J$11,MATCH(A11&"-"&B11,'④回収ファイル一覧'!$K$4:$K$11,0)),"")}
A12: 1 | B12: 1 | C12: B2 | D12: 驚く | E12: 反応する | F12: 46215 | G12: 4 | H12: ◯ | J12: {=IFERROR(INDEX('④回収ファイル一覧'!$G$4:$G$11,MATCH(A12&"-"&B12,'④回収ファイル一覧'!$K$4:$K$11,0)),"")} | K12: {=IFERROR(INDEX('④回収ファイル一覧'!$H$4:$H$11,MATCH(A12&"-"&B12,'④回収ファイル一覧'!$K$4:$K$11,0)),"")} | L12: {=IFERROR(INDEX('④回収ファイル一覧'!$I$4:$I$11,MATCH(A12&"-"&B12,'④回収ファイル一覧'!$K$4:$K$11,0)),"")} | M12: {=IFERROR(INDEX('④回収ファイル一覧'!$J$4:$J$11,MATCH(A12&"-"&B12,'④回収ファイル一覧'!$K$4:$K$11,0)),"")}
A13: 1 | B13: 1 | C13: B3 | D13: 怒る | E13: 反応する | F13: 46215 | G13: 3 | H13: ◯ | J13: {=IFERROR(INDEX('④回収ファイル一覧'!$G$4:$G$11,MATCH(A13&"-"&B13,'④回収ファイル一覧'!$K$4:$K$11,0)),"")} | K13: {=IFERROR(INDEX('④回収ファイル一覧'!$H$4:$H$11,MATCH(A13&"-"&B13,'④回収ファイル一覧'!$K$4:$K$11,0)),"")} | L13: {=IFERROR(INDEX('④回収ファイル一覧'!$I$4:$I$11,MATCH(A13&"-"&B13,'④回収ファイル一覧'!$K$4:$K$11,0)),"")} | M13: {=IFERROR(INDEX('④回収ファイル一覧'!$J$4:$J$11,MATCH(A13&"-"&B13,'④回収ファイル一覧'!$K$4:$K$11,0)),"")}
A14: 1 | B14: 1 | C14: B4 | D14: 静かに笑う（声量そのまま） | E14: 反応する | F14: 46215 | G14: 4 | H14: ◯ | J14: {=IFERROR(INDEX('④回収ファイル一覧'!$G$4:$G$11,MATCH(A14&"-"&B14,'④回収ファイル一覧'!$K$4:$K$11,0)),"")} | K14: {=IFERROR(INDEX('④回収ファイル一覧'!$H$4:$H$11,MATCH(A14&"-"&B14,'④回収ファイル一覧'!$K$4:$K$11,0)),"")} | L14: {=IFERROR(INDEX('④回収ファイル一覧'!$I$4:$I$11,MATCH(A14&"-"&B14,'④回収ファイル一覧'!$K$4:$K$11,0)),"")} | M14: {=IFERROR(INDEX('④回収ファイル一覧'!$J$4:$J$11,MATCH(A14&"-"&B14,'④回収ファイル一覧'!$K$4:$K$11,0)),"")}
A15: 1 | B15: 1 | C15: B5 | D15: ほめ言葉（ふだんの声） | E15: 反応する | F15: 46215 | G15: 5 | H15: ◯ | J15: {=IFERROR(INDEX('④回収ファイル一覧'!$G$4:$G$11,MATCH(A15&"-"&B15,'④回収ファイル一覧'!$K$4:$K$11,0)),"")} | K15: {=IFERROR(INDEX('④回収ファイル一覧'!$H$4:$H$11,MATCH(A15&"-"&B15,'④回収ファイル一覧'!$K$4:$K$11,0)),"")} | L15: {=IFERROR(INDEX('④回収ファイル一覧'!$I$4:$I$11,MATCH(A15&"-"&B15,'④回収ファイル一覧'!$K$4:$K$11,0)),"")} | M15: {=IFERROR(INDEX('④回収ファイル一覧'!$J$4:$J$11,MATCH(A15&"-"&B15,'④回収ファイル一覧'!$K$4:$K$11,0)),"")}
A16: 1 | B16: 1 | C16: B6 | D16: 感極まる | E16: 反応する | F16: 46215 | G16: 4 | H16: ◯ | J16: {=IFERROR(INDEX('④回収ファイル一覧'!$G$4:$G$11,MATCH(A16&"-"&B16,'④回収ファイル一覧'!$K$4:$K$11,0)),"")} | K16: {=IFERROR(INDEX('④回収ファイル一覧'!$H$4:$H$11,MATCH(A16&"-"&B16,'④回収ファイル一覧'!$K$4:$K$11,0)),"")} | L16: {=IFERROR(INDEX('④回収ファイル一覧'!$I$4:$I$11,MATCH(A16&"-"&B16,'④回収ファイル一覧'!$K$4:$K$11,0)),"")} | M16: {=IFERROR(INDEX('④回収ファイル一覧'!$J$4:$J$11,MATCH(A16&"-"&B16,'④回収ファイル一覧'!$K$4:$K$11,0)),"")}
A17: 1 | B17: 1 | C17: C1 | D17: 咳・くしゃみ・あくび | E17: 記録のみ | F17: 46215 | G17: 3 | I17: くしゃみ、あくびに反応 | J17: {=IFERROR(INDEX('④回収ファイル一覧'!$G$4:$G$11,MATCH(A17&"-"&B17,'④回収ファイル一覧'!$K$4:$K$11,0)),"")} | K17: {=IFERROR(INDEX('④回収ファイル一覧'!$H$4:$H$11,MATCH(A17&"-"&B17,'④回収ファイル一覧'!$K$4:$K$11,0)),"")} | L17: {=IFERROR(INDEX('④回収ファイル一覧'!$I$4:$I$11,MATCH(A17&"-"&B17,'④回収ファイル一覧'!$K$4:$K$11,0)),"")} | M17: {=IFERROR(INDEX('④回収ファイル一覧'!$J$4:$J$11,MATCH(A17&"-"&B17,'④回収ファイル一覧'!$K$4:$K$11,0)),"")}
A18: 1 | B18: 1 | C18: C2 | D18: 笑い続ける30秒 | E18: 2回以上反応が正解 | F18: 46215 | G18: 4 | J18: {=IFERROR(INDEX('④回収ファイル一覧'!$G$4:$G$11,MATCH(A18&"-"&B18,'④回収ファイル一覧'!$K$4:$K$11,0)),"")} | K18: {=IFERROR(INDEX('④回収ファイル一覧'!$H$4:$H$11,MATCH(A18&"-"&B18,'④回収ファイル一覧'!$K$4:$K$11,0)),"")} | L18: {=IFERROR(INDEX('④回収ファイル一覧'!$I$4:$I$11,MATCH(A18&"-"&B18,'④回収ファイル一覧'!$K$4:$K$11,0)),"")} | M18: {=IFERROR(INDEX('④回収ファイル一覧'!$J$4:$J$11,MATCH(A18&"-"&B18,'④回収ファイル一覧'!$K$4:$K$11,0)),"")}
A19: 1 | B19: 1 | C19: C3 | D19: 家族側が大声（テスター無言） | E19: 記録のみ | F19: 46215 | G19: 3 | H19: × | J19: {=IFERROR(INDEX('④回収ファイル一覧'!$G$4:$G$11,MATCH(A19&"-"&B19,'④回収ファイル一覧'!$K$4:$K$11,0)),"")} | K19: {=IFERROR(INDEX('④回収ファイル一覧'!$H$4:$H$11,MATCH(A19&"-"&B19,'④回収ファイル一覧'!$K$4:$K$11,0)),"")} | L19: {=IFERROR(INDEX('④回収ファイル一覧'!$I$4:$I$11,MATCH(A19&"-"&B19,'④回収ファイル一覧'!$K$4:$K$11,0)),"")} | M19: {=IFERROR(INDEX('④回収ファイル一覧'!$J$4:$J$11,MATCH(A19&"-"&B19,'④回収ファイル一覧'!$K$4:$K$11,0)),"")}
A20: 1 | B20: 2 | C20: A1 | D20: 静かにする | E20: 反応しない | F20: 46215 | G20: 0 | H20: ◯ | J20: {=IFERROR(INDEX('④回収ファイル一覧'!$G$4:$G$11,MATCH(A20&"-"&B20,'④回収ファイル一覧'!$K$4:$K$11,0)),"")} | K20: {=IFERROR(INDEX('④回収ファイル一覧'!$H$4:$H$11,MATCH(A20&"-"&B20,'④回収ファイル一覧'!$K$4:$K$11,0)),"")} | L20: {=IFERROR(INDEX('④回収ファイル一覧'!$I$4:$I$11,MATCH(A20&"-"&B20,'④回収ファイル一覧'!$K$4:$K$11,0)),"")} | M20: {=IFERROR(INDEX('④回収ファイル一覧'!$J$4:$J$11,MATCH(A20&"-"&B20,'④回収ファイル一覧'!$K$4:$K$11,0)),"")}
A21: 1 | B21: 2 | C21: A2 | D21: ふつうの雑談（10分） | E21: 反応しない | F21: 46215 | G21: 13 | H21: × | J21: {=IFERROR(INDEX('④回収ファイル一覧'!$G$4:$G$11,MATCH(A21&"-"&B21,'④回収ファイル一覧'!$K$4:$K$11,0)),"")} | K21: {=IFERROR(INDEX('④回収ファイル一覧'!$H$4:$H$11,MATCH(A21&"-"&B21,'④回収ファイル一覧'!$K$4:$K$11,0)),"")} | L21: {=IFERROR(INDEX('④回収ファイル一覧'!$I$4:$I$11,MATCH(A21&"-"&B21,'④回収ファイル一覧'!$K$4:$K$11,0)),"")} | M21: {=IFERROR(INDEX('④回収ファイル一覧'!$J$4:$J$11,MATCH(A21&"-"&B21,'④回収ファイル一覧'!$K$4:$K$11,0)),"")}
A22: 1 | B22: 2 | C22: A3 | D22: 本を読む | E22: 反応しない | F22: 46215 | G22: 13 | H22: × | J22: {=IFERROR(INDEX('④回収ファイル一覧'!$G$4:$G$11,MATCH(A22&"-"&B22,'④回収ファイル一覧'!$K$4:$K$11,0)),"")} | K22: {=IFERROR(INDEX('④回収ファイル一覧'!$H$4:$H$11,MATCH(A22&"-"&B22,'④回収ファイル一覧'!$K$4:$K$11,0)),"")} | L22: {=IFERROR(INDEX('④回収ファイル一覧'!$I$4:$I$11,MATCH(A22&"-"&B22,'④回収ファイル一覧'!$K$4:$K$11,0)),"")} | M22: {=IFERROR(INDEX('④回収ファイル一覧'!$J$4:$J$11,MATCH(A22&"-"&B22,'④回収ファイル一覧'!$K$4:$K$11,0)),"")}
A23: 1 | B23: 2 | C23: A4 | D23: 生活音を出す | E23: 反応しない | F23: 46215 | G23: 6 | H23: × | J23: {=IFERROR(INDEX('④回収ファイル一覧'!$G$4:$G$11,MATCH(A23&"-"&B23,'④回収ファイル一覧'!$K$4:$K$11,0)),"")} | K23: {=IFERROR(INDEX('④回収ファイル一覧'!$H$4:$H$11,MATCH(A23&"-"&B23,'④回収ファイル一覧'!$K$4:$K$11,0)),"")} | L23: {=IFERROR(INDEX('④回収ファイル一覧'!$I$4:$I$11,MATCH(A23&"-"&B23,'④回収ファイル一覧'!$K$4:$K$11,0)),"")} | M23: {=IFERROR(INDEX('④回収ファイル一覧'!$J$4:$J$11,MATCH(A23&"-"&B23,'④回収ファイル一覧'!$K$4:$K$11,0)),"")}
A24: 1 | B24: 2 | C24: A5 | D24: 最初のあいさつ（かけ直し） | E24: 反応しない | F24: 46215 | G24: 1 | H24: × | J24: {=IFERROR(INDEX('④回収ファイル一覧'!$G$4:$G$11,MATCH(A24&"-"&B24,'④回収ファイル一覧'!$K$4:$K$11,0)),"")} | K24: {=IFERROR(INDEX('④回収ファイル一覧'!$H$4:$H$11,MATCH(A24&"-"&B24,'④回収ファイル一覧'!$K$4:$K$11,0)),"")} | L24: {=IFERROR(INDEX('④回収ファイル一覧'!$I$4:$I$11,MATCH(A24&"-"&B24,'④回収ファイル一覧'!$K$4:$K$11,0)),"")} | M24: {=IFERROR(INDEX('④回収ファイル一覧'!$J$4:$J$11,MATCH(A24&"-"&B24,'④回収ファイル一覧'!$K$4:$K$11,0)),"")}
A25: 1 | B25: 2 | C25: A6 | D25: 立って戻る | E25: 反応しない | F25: 46215 | G25: 10 | H25: × | J25: {=IFERROR(INDEX('④回収ファイル一覧'!$G$4:$G$11,MATCH(A25&"-"&B25,'④回収ファイル一覧'!$K$4:$K$11,0)),"")} | K25: {=IFERROR(INDEX('④回収ファイル一覧'!$H$4:$H$11,MATCH(A25&"-"&B25,'④回収ファイル一覧'!$K$4:$K$11,0)),"")} | L25: {=IFERROR(INDEX('④回収ファイル一覧'!$I$4:$I$11,MATCH(A25&"-"&B25,'④回収ファイル一覧'!$K$4:$K$11,0)),"")} | M25: {=IFERROR(INDEX('④回収ファイル一覧'!$J$4:$J$11,MATCH(A25&"-"&B25,'④回収ファイル一覧'!$K$4:$K$11,0)),"")}
A26: 1 | B26: 2 | C26: B1 | D26: 声を出して笑う | E26: 反応する | F26: 46215 | G26: 6 | H26: ◯ | J26: {=IFERROR(INDEX('④回収ファイル一覧'!$G$4:$G$11,MATCH(A26&"-"&B26,'④回収ファイル一覧'!$K$4:$K$11,0)),"")} | K26: {=IFERROR(INDEX('④回収ファイル一覧'!$H$4:$H$11,MATCH(A26&"-"&B26,'④回収ファイル一覧'!$K$4:$K$11,0)),"")} | L26: {=IFERROR(INDEX('④回収ファイル一覧'!$I$4:$I$11,MATCH(A26&"-"&B26,'④回収ファイル一覧'!$K$4:$K$11,0)),"")} | M26: {=IFERROR(INDEX('④回収ファイル一覧'!$J$4:$J$11,MATCH(A26&"-"&B26,'④回収ファイル一覧'!$K$4:$K$11,0)),"")}
A27: 1 | B27: 2 | C27: B2 | D27: 驚く | E27: 反応する | F27: 46215 | G27: 5 | H27: ◯ | J27: {=IFERROR(INDEX('④回収ファイル一覧'!$G$4:$G$11,MATCH(A27&"-"&B27,'④回収ファイル一覧'!$K$4:$K$11,0)),"")} | K27: {=IFERROR(INDEX('④回収ファイル一覧'!$H$4:$H$11,MATCH(A27&"-"&B27,'④回収ファイル一覧'!$K$4:$K$11,0)),"")} | L27: {=IFERROR(INDEX('④回収ファイル一覧'!$I$4:$I$11,MATCH(A27&"-"&B27,'④回収ファイル一覧'!$K$4:$K$11,0)),"")} | M27: {=IFERROR(INDEX('④回収ファイル一覧'!$J$4:$J$11,MATCH(A27&"-"&B27,'④回収ファイル一覧'!$K$4:$K$11,0)),"")}
A28: 1 | B28: 2 | C28: B3 | D28: 怒る | E28: 反応する | F28: 46215 | G28: 3 | H28: ◯ | J28: {=IFERROR(INDEX('④回収ファイル一覧'!$G$4:$G$11,MATCH(A28&"-"&B28,'④回収ファイル一覧'!$K$4:$K$11,0)),"")} | K28: {=IFERROR(INDEX('④回収ファイル一覧'!$H$4:$H$11,MATCH(A28&"-"&B28,'④回収ファイル一覧'!$K$4:$K$11,0)),"")} | L28: {=IFERROR(INDEX('④回収ファイル一覧'!$I$4:$I$11,MATCH(A28&"-"&B28,'④回収ファイル一覧'!$K$4:$K$11,0)),"")} | M28: {=IFERROR(INDEX('④回収ファイル一覧'!$J$4:$J$11,MATCH(A28&"-"&B28,'④回収ファイル一覧'!$K$4:$K$11,0)),"")}
A29: 1 | B29: 2 | C29: B4 | D29: 静かに笑う（声量そのまま） | E29: 反応する | F29: 46215 | G29: 2 | H29: ◯ | J29: {=IFERROR(INDEX('④回収ファイル一覧'!$G$4:$G$11,MATCH(A29&"-"&B29,'④回収ファイル一覧'!$K$4:$K$11,0)),"")} | K29: {=IFERROR(INDEX('④回収ファイル一覧'!$H$4:$H$11,MATCH(A29&"-"&B29,'④回収ファイル一覧'!$K$4:$K$11,0)),"")} | L29: {=IFERROR(INDEX('④回収ファイル一覧'!$I$4:$I$11,MATCH(A29&"-"&B29,'④回収ファイル一覧'!$K$4:$K$11,0)),"")} | M29: {=IFERROR(INDEX('④回収ファイル一覧'!$J$4:$J$11,MATCH(A29&"-"&B29,'④回収ファイル一覧'!$K$4:$K$11,0)),"")}
A30: 1 | B30: 2 | C30: B5 | D30: ほめ言葉（ふだんの声） | E30: 反応する | F30: 46215 | G30: 4 | H30: ◯ | J30: {=IFERROR(INDEX('④回収ファイル一覧'!$G$4:$G$11,MATCH(A30&"-"&B30,'④回収ファイル一覧'!$K$4:$K$11,0)),"")} | K30: {=IFERROR(INDEX('④回収ファイル一覧'!$H$4:$H$11,MATCH(A30&"-"&B30,'④回収ファイル一覧'!$K$4:$K$11,0)),"")} | L30: {=IFERROR(INDEX('④回収ファイル一覧'!$I$4:$I$11,MATCH(A30&"-"&B30,'④回収ファイル一覧'!$K$4:$K$11,0)),"")} | M30: {=IFERROR(INDEX('④回収ファイル一覧'!$J$4:$J$11,MATCH(A30&"-"&B30,'④回収ファイル一覧'!$K$4:$K$11,0)),"")}
A31: 1 | B31: 2 | C31: B6 | D31: 感極まる | E31: 反応する | F31: 46215 | G31: 4 | H31: ◯ | J31: {=IFERROR(INDEX('④回収ファイル一覧'!$G$4:$G$11,MATCH(A31&"-"&B31,'④回収ファイル一覧'!$K$4:$K$11,0)),"")} | K31: {=IFERROR(INDEX('④回収ファイル一覧'!$H$4:$H$11,MATCH(A31&"-"&B31,'④回収ファイル一覧'!$K$4:$K$11,0)),"")} | L31: {=IFERROR(INDEX('④回収ファイル一覧'!$I$4:$I$11,MATCH(A31&"-"&B31,'④回収ファイル一覧'!$K$4:$K$11,0)),"")} | M31: {=IFERROR(INDEX('④回収ファイル一覧'!$J$4:$J$11,MATCH(A31&"-"&B31,'④回収ファイル一覧'!$K$4:$K$11,0)),"")}
A32: 1 | B32: 2 | C32: C1 | D32: 咳・くしゃみ・あくび | E32: 記録のみ | F32: 46215 | G32: 2 | I32: 咳、くしゃみ | J32: {=IFERROR(INDEX('④回収ファイル一覧'!$G$4:$G$11,MATCH(A32&"-"&B32,'④回収ファイル一覧'!$K$4:$K$11,0)),"")} | K32: {=IFERROR(INDEX('④回収ファイル一覧'!$H$4:$H$11,MATCH(A32&"-"&B32,'④回収ファイル一覧'!$K$4:$K$11,0)),"")} | L32: {=IFERROR(INDEX('④回収ファイル一覧'!$I$4:$I$11,MATCH(A32&"-"&B32,'④回収ファイル一覧'!$K$4:$K$11,0)),"")} | M32: {=IFERROR(INDEX('④回収ファイル一覧'!$J$4:$J$11,MATCH(A32&"-"&B32,'④回収ファイル一覧'!$K$4:$K$11,0)),"")}
A33: 1 | B33: 2 | C33: C2 | D33: 笑い続ける30秒 | E33: 2回以上反応が正解 | F33: 46215 | G33: 5 | J33: {=IFERROR(INDEX('④回収ファイル一覧'!$G$4:$G$11,MATCH(A33&"-"&B33,'④回収ファイル一覧'!$K$4:$K$11,0)),"")} | K33: {=IFERROR(INDEX('④回収ファイル一覧'!$H$4:$H$11,MATCH(A33&"-"&B33,'④回収ファイル一覧'!$K$4:$K$11,0)),"")} | L33: {=IFERROR(INDEX('④回収ファイル一覧'!$I$4:$I$11,MATCH(A33&"-"&B33,'④回収ファイル一覧'!$K$4:$K$11,0)),"")} | M33: {=IFERROR(INDEX('④回収ファイル一覧'!$J$4:$J$11,MATCH(A33&"-"&B33,'④回収ファイル一覧'!$K$4:$K$11,0)),"")}
A34: 1 | B34: 2 | C34: C3 | D34: 家族側が大声（テスター無言） | E34: 記録のみ | F34: 46215 | G34: 3 | H34: × | J34: {=IFERROR(INDEX('④回収ファイル一覧'!$G$4:$G$11,MATCH(A34&"-"&B34,'④回収ファイル一覧'!$K$4:$K$11,0)),"")} | K34: {=IFERROR(INDEX('④回収ファイル一覧'!$H$4:$H$11,MATCH(A34&"-"&B34,'④回収ファイル一覧'!$K$4:$K$11,0)),"")} | L34: {=IFERROR(INDEX('④回収ファイル一覧'!$I$4:$I$11,MATCH(A34&"-"&B34,'④回収ファイル一覧'!$K$4:$K$11,0)),"")} | M34: {=IFERROR(INDEX('④回収ファイル一覧'!$J$4:$J$11,MATCH(A34&"-"&B34,'④回収ファイル一覧'!$K$4:$K$11,0)),"")}
A35: 1 | B35: 3 | C35: A1 | D35: 静かにする | E35: 反応しない | F35: 46219 | G35: 0 | H35: ◯ | J35: {=IFERROR(INDEX('④回収ファイル一覧'!$G$4:$G$11,MATCH(A35&"-"&B35,'④回収ファイル一覧'!$K$4:$K$11,0)),"")} | K35: {=IFERROR(INDEX('④回収ファイル一覧'!$H$4:$H$11,MATCH(A35&"-"&B35,'④回収ファイル一覧'!$K$4:$K$11,0)),"")} | L35: {=IFERROR(INDEX('④回収ファイル一覧'!$I$4:$I$11,MATCH(A35&"-"&B35,'④回収ファイル一覧'!$K$4:$K$11,0)),"")} | M35: {=IFERROR(INDEX('④回収ファイル一覧'!$J$4:$J$11,MATCH(A35&"-"&B35,'④回収ファイル一覧'!$K$4:$K$11,0)),"")}
A36: 1 | B36: 3 | C36: A2 | D36: ふつうの雑談（10分） | E36: 反応しない | F36: 46219 | G36: 11 | H36: × | J36: {=IFERROR(INDEX('④回収ファイル一覧'!$G$4:$G$11,MATCH(A36&"-"&B36,'④回収ファイル一覧'!$K$4:$K$11,0)),"")} | K36: {=IFERROR(INDEX('④回収ファイル一覧'!$H$4:$H$11,MATCH(A36&"-"&B36,'④回収ファイル一覧'!$K$4:$K$11,0)),"")} | L36: {=IFERROR(INDEX('④回収ファイル一覧'!$I$4:$I$11,MATCH(A36&"-"&B36,'④回収ファイル一覧'!$K$4:$K$11,0)),"")} | M36: {=IFERROR(INDEX('④回収ファイル一覧'!$J$4:$J$11,MATCH(A36&"-"&B36,'④回収ファイル一覧'!$K$4:$K$11,0)),"")}
A37: 1 | B37: 3 | C37: A3 | D37: 本を読む | E37: 反応しない | F37: 46219 | G37: 9 | H37: × | J37: {=IFERROR(INDEX('④回収ファイル一覧'!$G$4:$G$11,MATCH(A37&"-"&B37,'④回収ファイル一覧'!$K$4:$K$11,0)),"")} | K37: {=IFERROR(INDEX('④回収ファイル一覧'!$H$4:$H$11,MATCH(A37&"-"&B37,'④回収ファイル一覧'!$K$4:$K$11,0)),"")} | L37: {=IFERROR(INDEX('④回収ファイル一覧'!$I$4:$I$11,MATCH(A37&"-"&B37,'④回収ファイル一覧'!$K$4:$K$11,0)),"")} | M37: {=IFERROR(INDEX('④回収ファイル一覧'!$J$4:$J$11,MATCH(A37&"-"&B37,'④回収ファイル一覧'!$K$4:$K$11,0)),"")}
A38: 1 | B38: 3 | C38: A4 | D38: 生活音を出す | E38: 反応しない | F38: 46219 | G38: 9 | H38: × | J38: {=IFERROR(INDEX('④回収ファイル一覧'!$G$4:$G$11,MATCH(A38&"-"&B38,'④回収ファイル一覧'!$K$4:$K$11,0)),"")} | K38: {=IFERROR(INDEX('④回収ファイル一覧'!$H$4:$H$11,MATCH(A38&"-"&B38,'④回収ファイル一覧'!$K$4:$K$11,0)),"")} | L38: {=IFERROR(INDEX('④回収ファイル一覧'!$I$4:$I$11,MATCH(A38&"-"&B38,'④回収ファイル一覧'!$K$4:$K$11,0)),"")} | M38: {=IFERROR(INDEX('④回収ファイル一覧'!$J$4:$J$11,MATCH(A38&"-"&B38,'④回収ファイル一覧'!$K$4:$K$11,0)),"")}
A39: 1 | B39: 3 | C39: A5 | D39: 最初のあいさつ（かけ直し） | E39: 反応しない | F39: 46219 | G39: 3 | H39: × | J39: {=IFERROR(INDEX('④回収ファイル一覧'!$G$4:$G$11,MATCH(A39&"-"&B39,'④回収ファイル一覧'!$K$4:$K$11,0)),"")} | K39: {=IFERROR(INDEX('④回収ファイル一覧'!$H$4:$H$11,MATCH(A39&"-"&B39,'④回収ファイル一覧'!$K$4:$K$11,0)),"")} | L39: {=IFERROR(INDEX('④回収ファイル一覧'!$I$4:$I$11,MATCH(A39&"-"&B39,'④回収ファイル一覧'!$K$4:$K$11,0)),"")} | M39: {=IFERROR(INDEX('④回収ファイル一覧'!$J$4:$J$11,MATCH(A39&"-"&B39,'④回収ファイル一覧'!$K$4:$K$11,0)),"")}
A40: 1 | B40: 3 | C40: A6 | D40: 立って戻る | E40: 反応しない | F40: 46219 | G40: 10 | H40: × | J40: {=IFERROR(INDEX('④回収ファイル一覧'!$G$4:$G$11,MATCH(A40&"-"&B40,'④回収ファイル一覧'!$K$4:$K$11,0)),"")} | K40: {=IFERROR(INDEX('④回収ファイル一覧'!$H$4:$H$11,MATCH(A40&"-"&B40,'④回収ファイル一覧'!$K$4:$K$11,0)),"")} | L40: {=IFERROR(INDEX('④回収ファイル一覧'!$I$4:$I$11,MATCH(A40&"-"&B40,'④回収ファイル一覧'!$K$4:$K$11,0)),"")} | M40: {=IFERROR(INDEX('④回収ファイル一覧'!$J$4:$J$11,MATCH(A40&"-"&B40,'④回収ファイル一覧'!$K$4:$K$11,0)),"")}
...

Sheet ③実施記録_旧
A1: チェックリスト — 実施記録（メイン）
A3: ラウンド | B3: セッション(Day) | C3: 番号 | D3: 場面 | E3: 正解 | F3: 実施日 | G3: 反応した回数 | H3: 期待どおり？ | I3: メモ | J3: 高齢者役_環境 | K3: 高齢者役_マイク | L3: 家族役_環境 | M3: 家族役_マイク
A4: 例 | B4: 1 | C4: A1 | D4: 静かにする | E4: 反応しない | F4: 7/15 | G4: 0 | H4: ◯ | I4: 問題なし | J4: {=IFERROR(INDEX('④回収ファイル一覧'!$G$4:$G$11,MATCH(A4&"-"&B4,'④回収ファイル一覧'!$K$4:$K$11,0)),"")} | K4: {=IFERROR(INDEX('④回収ファイル一覧'!$H$4:$H$11,MATCH(A4&"-"&B4,'④回収ファイル一覧'!$K$4:$K$11,0)),"")} | L4: {=IFERROR(INDEX('④回収ファイル一覧'!$I$4:$I$11,MATCH(A4&"-"&B4,'④回収ファイル一覧'!$K$4:$K$11,0)),"")} | M4: {=IFERROR(INDEX('④回収ファイル一覧'!$J$4:$J$11,MATCH(A4&"-"&B4,'④回収ファイル一覧'!$K$4:$K$11,0)),"")}
A5: 1 | B5: 2 | C5: A1 | D5: 静かにする | E5: 反応しない | F5: 46215 | G5: 1 | H5: × | I5: 機械音みたいなものに反応 | J5: {=IFERROR(INDEX('④回収ファイル一覧'!$G$4:$G$11,MATCH(A5&"-"&B5,'④回収ファイル一覧'!$K$4:$K$11,0)),"")} | K5: {=IFERROR(INDEX('④回収ファイル一覧'!$H$4:$H$11,MATCH(A5&"-"&B5,'④回収ファイル一覧'!$K$4:$K$11,0)),"")} | L5: {=IFERROR(INDEX('④回収ファイル一覧'!$I$4:$I$11,MATCH(A5&"-"&B5,'④回収ファイル一覧'!$K$4:$K$11,0)),"")} | M5: {=IFERROR(INDEX('④回収ファイル一覧'!$J$4:$J$11,MATCH(A5&"-"&B5,'④回収ファイル一覧'!$K$4:$K$11,0)),"")}
A6: 1 | B6: 2 | C6: A2 | D6: ふつうの雑談（10分） | E6: 反応しない | F6: 46215 | G6: 9 | H6: × | I6: 平坦な声で世間話をしているが9回も反応した | J6: {=IFERROR(INDEX('④回収ファイル一覧'!$G$4:$G$11,MATCH(A6&"-"&B6,'④回収ファイル一覧'!$K$4:$K$11,0)),"")} | K6: {=IFERROR(INDEX('④回収ファイル一覧'!$H$4:$H$11,MATCH(A6&"-"&B6,'④回収ファイル一覧'!$K$4:$K$11,0)),"")} | L6: {=IFERROR(INDEX('④回収ファイル一覧'!$I$4:$I$11,MATCH(A6&"-"&B6,'④回収ファイル一覧'!$K$4:$K$11,0)),"")} | M6: {=IFERROR(INDEX('④回収ファイル一覧'!$J$4:$J$11,MATCH(A6&"-"&B6,'④回収ファイル一覧'!$K$4:$K$11,0)),"")}
A7: 1 | B7: 2 | C7: A3 | D7: 本を読む | E7: 反応しない | F7: 46215 | G7: 14 | H7: × | J7: {=IFERROR(INDEX('④回収ファイル一覧'!$G$4:$G$11,MATCH(A7&"-"&B7,'④回収ファイル一覧'!$K$4:$K$11,0)),"")} | K7: {=IFERROR(INDEX('④回収ファイル一覧'!$H$4:$H$11,MATCH(A7&"-"&B7,'④回収ファイル一覧'!$K$4:$K$11,0)),"")} | L7: {=IFERROR(INDEX('④回収ファイル一覧'!$I$4:$I$11,MATCH(A7&"-"&B7,'④回収ファイル一覧'!$K$4:$K$11,0)),"")} | M7: {=IFERROR(INDEX('④回収ファイル一覧'!$J$4:$J$11,MATCH(A7&"-"&B7,'④回収ファイル一覧'!$K$4:$K$11,0)),"")}
A8: 1 | B8: 2 | C8: A4 | D8: 生活音を出す | E8: 反応しない | F8: 46215 | G8: 5 | H8: × | I8: 掃除機の音、ペットボトルに水を入れる音、 | J8: {=IFERROR(INDEX('④回収ファイル一覧'!$G$4:$G$11,MATCH(A8&"-"&B8,'④回収ファイル一覧'!$K$4:$K$11,0)),"")} | K8: {=IFERROR(INDEX('④回収ファイル一覧'!$H$4:$H$11,MATCH(A8&"-"&B8,'④回収ファイル一覧'!$K$4:$K$11,0)),"")} | L8: {=IFERROR(INDEX('④回収ファイル一覧'!$I$4:$I$11,MATCH(A8&"-"&B8,'④回収ファイル一覧'!$K$4:$K$11,0)),"")} | M8: {=IFERROR(INDEX('④回収ファイル一覧'!$J$4:$J$11,MATCH(A8&"-"&B8,'④回収ファイル一覧'!$K$4:$K$11,0)),"")}
A9: 1 | B9: 2 | C9: A5 | D9: 最初のあいさつ（かけ直し） | E9: 反応しない | F9: 46215 | G9: 1 | H9: × | J9: {=IFERROR(INDEX('④回収ファイル一覧'!$G$4:$G$11,MATCH(A9&"-"&B9,'④回収ファイル一覧'!$K$4:$K$11,0)),"")} | K9: {=IFERROR(INDEX('④回収ファイル一覧'!$H$4:$H$11,MATCH(A9&"-"&B9,'④回収ファイル一覧'!$K$4:$K$11,0)),"")} | L9: {=IFERROR(INDEX('④回収ファイル一覧'!$I$4:$I$11,MATCH(A9&"-"&B9,'④回収ファイル一覧'!$K$4:$K$11,0)),"")} | M9: {=IFERROR(INDEX('④回収ファイル一覧'!$J$4:$J$11,MATCH(A9&"-"&B9,'④回収ファイル一覧'!$K$4:$K$11,0)),"")}
A10: 1 | B10: 2 | C10: A6 | D10: 立って戻る | E10: 反応しない | F10: 46215 | G10: 8 | H10: × | I10: 途中で落ちたので3回目のログに入っている | J10: {=IFERROR(INDEX('④回収ファイル一覧'!$G$4:$G$11,MATCH(A10&"-"&B10,'④回収ファイル一覧'!$K$4:$K$11,0)),"")} | K10: {=IFERROR(INDEX('④回収ファイル一覧'!$H$4:$H$11,MATCH(A10&"-"&B10,'④回収ファイル一覧'!$K$4:$K$11,0)),"")} | L10: {=IFERROR(INDEX('④回収ファイル一覧'!$I$4:$I$11,MATCH(A10&"-"&B10,'④回収ファイル一覧'!$K$4:$K$11,0)),"")} | M10: {=IFERROR(INDEX('④回収ファイル一覧'!$J$4:$J$11,MATCH(A10&"-"&B10,'④回収ファイル一覧'!$K$4:$K$11,0)),"")}
A11: 1 | B11: 2 | C11: B1 | D11: 声を出して笑う | E11: 反応する | F11: 46215 | G11: 5 | J11: {=IFERROR(INDEX('④回収ファイル一覧'!$G$4:$G$11,MATCH(A11&"-"&B11,'④回収ファイル一覧'!$K$4:$K$11,0)),"")} | K11: {=IFERROR(INDEX('④回収ファイル一覧'!$H$4:$H$11,MATCH(A11&"-"&B11,'④回収ファイル一覧'!$K$4:$K$11,0)),"")} | L11: {=IFERROR(INDEX('④回収ファイル一覧'!$I$4:$I$11,MATCH(A11&"-"&B11,'④回収ファイル一覧'!$K$4:$K$11,0)),"")} | M11: {=IFERROR(INDEX('④回収ファイル一覧'!$J$4:$J$11,MATCH(A11&"-"&B11,'④回収ファイル一覧'!$K$4:$K$11,0)),"")}
A12: 1 | B12: 2 | C12: B2 | D12: 驚く | E12: 反応する | F12: 46215 | G12: 4 | J12: {=IFERROR(INDEX('④回収ファイル一覧'!$G$4:$G$11,MATCH(A12&"-"&B12,'④回収ファイル一覧'!$K$4:$K$11,0)),"")} | K12: {=IFERROR(INDEX('④回収ファイル一覧'!$H$4:$H$11,MATCH(A12&"-"&B12,'④回収ファイル一覧'!$K$4:$K$11,0)),"")} | L12: {=IFERROR(INDEX('④回収ファイル一覧'!$I$4:$I$11,MATCH(A12&"-"&B12,'④回収ファイル一覧'!$K$4:$K$11,0)),"")} | M12: {=IFERROR(INDEX('④回収ファイル一覧'!$J$4:$J$11,MATCH(A12&"-"&B12,'④回収ファイル一覧'!$K$4:$K$11,0)),"")}
A13: 1 | B13: 2 | C13: B3 | D13: 怒る | E13: 反応する | F13: 46215 | G13: 3 | J13: {=IFERROR(INDEX('④回収ファイル一覧'!$G$4:$G$11,MATCH(A13&"-"&B13,'④回収ファイル一覧'!$K$4:$K$11,0)),"")} | K13: {=IFERROR(INDEX('④回収ファイル一覧'!$H$4:$H$11,MATCH(A13&"-"&B13,'④回収ファイル一覧'!$K$4:$K$11,0)),"")} | L13: {=IFERROR(INDEX('④回収ファイル一覧'!$I$4:$I$11,MATCH(A13&"-"&B13,'④回収ファイル一覧'!$K$4:$K$11,0)),"")} | M13: {=IFERROR(INDEX('④回収ファイル一覧'!$J$4:$J$11,MATCH(A13&"-"&B13,'④回収ファイル一覧'!$K$4:$K$11,0)),"")}
A14: 1 | B14: 2 | C14: B4 | D14: 静かに笑う（声量そのまま） | E14: 反応する | F14: 46215 | G14: 4 | J14: {=IFERROR(INDEX('④回収ファイル一覧'!$G$4:$G$11,MATCH(A14&"-"&B14,'④回収ファイル一覧'!$K$4:$K$11,0)),"")} | K14: {=IFERROR(INDEX('④回収ファイル一覧'!$H$4:$H$11,MATCH(A14&"-"&B14,'④回収ファイル一覧'!$K$4:$K$11,0)),"")} | L14: {=IFERROR(INDEX('④回収ファイル一覧'!$I$4:$I$11,MATCH(A14&"-"&B14,'④回収ファイル一覧'!$K$4:$K$11,0)),"")} | M14: {=IFERROR(INDEX('④回収ファイル一覧'!$J$4:$J$11,MATCH(A14&"-"&B14,'④回収ファイル一覧'!$K$4:$K$11,0)),"")}
A15: 1 | B15: 2 | C15: B5 | D15: ほめ言葉（ふだんの声） | E15: 反応する | F15: 46215 | G15: 5 | J15: {=IFERROR(INDEX('④回収ファイル一覧'!$G$4:$G$11,MATCH(A15&"-"&B15,'④回収ファイル一覧'!$K$4:$K$11,0)),"")} | K15: {=IFERROR(INDEX('④回収ファイル一覧'!$H$4:$H$11,MATCH(A15&"-"&B15,'④回収ファイル一覧'!$K$4:$K$11,0)),"")} | L15: {=IFERROR(INDEX('④回収ファイル一覧'!$I$4:$I$11,MATCH(A15&"-"&B15,'④回収ファイル一覧'!$K$4:$K$11,0)),"")} | M15: {=IFERROR(INDEX('④回収ファイル一覧'!$J$4:$J$11,MATCH(A15&"-"&B15,'④回収ファイル一覧'!$K$4:$K$11,0)),"")}
A16: 1 | B16: 2 | C16: B6 | D16: 感極まる | E16: 反応する | F16: 46215 | G16: 4 | J16: {=IFERROR(INDEX('④回収ファイル一覧'!$G$4:$G$11,MATCH(A16&"-"&B16,'④回収ファイル一覧'!$K$4:$K$11,0)),"")} | K16: {=IFERROR(INDEX('④回収ファイル一覧'!$H$4:$H$11,MATCH(A16&"-"&B16,'④回収ファイル一覧'!$K$4:$K$11,0)),"")} | L16: {=IFERROR(INDEX('④回収ファイル一覧'!$I$4:$I$11,MATCH(A16&"-"&B16,'④回収ファイル一覧'!$K$4:$K$11,0)),"")} | M16: {=IFERROR(INDEX('④回収ファイル一覧'!$J$4:$J$11,MATCH(A16&"-"&B16,'④回収ファイル一覧'!$K$4:$K$11,0)),"")}
A17: 1 | B17: 2 | C17: C1 | D17: 咳・くしゃみ・あくび | E17: 記録のみ | F17: 46215 | G17: 3 | I17: くしゃみ、あくびに反応 | J17: {=IFERROR(INDEX('④回収ファイル一覧'!$G$4:$G$11,MATCH(A17&"-"&B17,'④回収ファイル一覧'!$K$4:$K$11,0)),"")} | K17: {=IFERROR(INDEX('④回収ファイル一覧'!$H$4:$H$11,MATCH(A17&"-"&B17,'④回収ファイル一覧'!$K$4:$K$11,0)),"")} | L17: {=IFERROR(INDEX('④回収ファイル一覧'!$I$4:$I$11,MATCH(A17&"-"&B17,'④回収ファイル一覧'!$K$4:$K$11,0)),"")} | M17: {=IFERROR(INDEX('④回収ファイル一覧'!$J$4:$J$11,MATCH(A17&"-"&B17,'④回収ファイル一覧'!$K$4:$K$11,0)),"")}
A18: 1 | B18: 2 | C18: C2 | D18: 笑い続ける30秒 | E18: 2回以上反応が正解 | F18: 46215 | G18: 4 | J18: {=IFERROR(INDEX('④回収ファイル一覧'!$G$4:$G$11,MATCH(A18&"-"&B18,'④回収ファイル一覧'!$K$4:$K$11,0)),"")} | K18: {=IFERROR(INDEX('④回収ファイル一覧'!$H$4:$H$11,MATCH(A18&"-"&B18,'④回収ファイル一覧'!$K$4:$K$11,0)),"")} | L18: {=IFERROR(INDEX('④回収ファイル一覧'!$I$4:$I$11,MATCH(A18&"-"&B18,'④回収ファイル一覧'!$K$4:$K$11,0)),"")} | M18: {=IFERROR(INDEX('④回収ファイル一覧'!$J$4:$J$11,MATCH(A18&"-"&B18,'④回収ファイル一覧'!$K$4:$K$11,0)),"")}
A19: 1 | B19: 2 | C19: C3 | D19: 家族側が大声（テスター無言） | E19: 記録のみ | F19: 46215 | G19: 3 | J19: {=IFERROR(INDEX('④回収ファイル一覧'!$G$4:$G$11,MATCH(A19&"-"&B19,'④回収ファイル一覧'!$K$4:$K$11,0)),"")} | K19: {=IFERROR(INDEX('④回収ファイル一覧'!$H$4:$H$11,MATCH(A19&"-"&B19,'④回収ファイル一覧'!$K$4:$K$11,0)),"")} | L19: {=IFERROR(INDEX('④回収ファイル一覧'!$I$4:$I$11,MATCH(A19&"-"&B19,'④回収ファイル一覧'!$K$4:$K$11,0)),"")} | M19: {=IFERROR(INDEX('④回収ファイル一覧'!$J$4:$J$11,MATCH(A19&"-"&B19,'④回収ファイル一覧'!$K$4:$K$11,0)),"")}
A20: 1 | B20: 3 | C20: A1 | D20: 静かにする | E20: 反応しない | G20: 0 | J20: {=IFERROR(INDEX('④回収ファイル一覧'!$G$4:$G$11,MATCH(A20&"-"&B20,'④回収ファイル一覧'!$K$4:$K$11,0)),"")} | K20: {=IFERROR(INDEX('④回収ファイル一覧'!$H$4:$H$11,MATCH(A20&"-"&B20,'④回収ファイル一覧'!$K$4:$K$11,0)),"")} | L20: {=IFERROR(INDEX('④回収ファイル一覧'!$I$4:$I$11,MATCH(A20&"-"&B20,'④回収ファイル一覧'!$K$4:$K$11,0)),"")} | M20: {=IFERROR(INDEX('④回収ファイル一覧'!$J$4:$J$11,MATCH(A20&"-"&B20,'④回収ファイル一覧'!$K$4:$K$11,0)),"")}
A21: 1 | B21: 3 | C21: A2 | D21: ふつうの雑談（10分） | E21: 反応しない | G21: 13 | J21: {=IFERROR(INDEX('④回収ファイル一覧'!$G$4:$G$11,MATCH(A21&"-"&B21,'④回収ファイル一覧'!$K$4:$K$11,0)),"")} | K21: {=IFERROR(INDEX('④回収ファイル一覧'!$H$4:$H$11,MATCH(A21&"-"&B21,'④回収ファイル一覧'!$K$4:$K$11,0)),"")} | L21: {=IFERROR(INDEX('④回収ファイル一覧'!$I$4:$I$11,MATCH(A21&"-"&B21,'④回収ファイル一覧'!$K$4:$K$11,0)),"")} | M21: {=IFERROR(INDEX('④回収ファイル一覧'!$J$4:$J$11,MATCH(A21&"-"&B21,'④回収ファイル一覧'!$K$4:$K$11,0)),"")}
A22: 1 | B22: 3 | C22: A3 | D22: 本を読む | E22: 反応しない | G22: 13 | J22: {=IFERROR(INDEX('④回収ファイル一覧'!$G$4:$G$11,MATCH(A22&"-"&B22,'④回収ファイル一覧'!$K$4:$K$11,0)),"")} | K22: {=IFERROR(INDEX('④回収ファイル一覧'!$H$4:$H$11,MATCH(A22&"-"&B22,'④回収ファイル一覧'!$K$4:$K$11,0)),"")} | L22: {=IFERROR(INDEX('④回収ファイル一覧'!$I$4:$I$11,MATCH(A22&"-"&B22,'④回収ファイル一覧'!$K$4:$K$11,0)),"")} | M22: {=IFERROR(INDEX('④回収ファイル一覧'!$J$4:$J$11,MATCH(A22&"-"&B22,'④回収ファイル一覧'!$K$4:$K$11,0)),"")}
A23: 1 | B23: 3 | C23: A4 | D23: 生活音を出す | E23: 反応しない | G23: 6 | J23: {=IFERROR(INDEX('④回収ファイル一覧'!$G$4:$G$11,MATCH(A23&"-"&B23,'④回収ファイル一覧'!$K$4:$K$11,0)),"")} | K23: {=IFERROR(INDEX('④回収ファイル一覧'!$H$4:$H$11,MATCH(A23&"-"&B23,'④回収ファイル一覧'!$K$4:$K$11,0)),"")} | L23: {=IFERROR(INDEX('④回収ファイル一覧'!$I$4:$I$11,MATCH(A23&"-"&B23,'④回収ファイル一覧'!$K$4:$K$11,0)),"")} | M23: {=IFERROR(INDEX('④回収ファイル一覧'!$J$4:$J$11,MATCH(A23&"-"&B23,'④回収ファイル一覧'!$K$4:$K$11,0)),"")}
A24: 1 | B24: 3 | C24: A5 | D24: 最初のあいさつ（かけ直し） | E24: 反応しない | G24: 1 | J24: {=IFERROR(INDEX('④回収ファイル一覧'!$G$4:$G$11,MATCH(A24&"-"&B24,'④回収ファイル一覧'!$K$4:$K$11,0)),"")} | K24: {=IFERROR(INDEX('④回収ファイル一覧'!$H$4:$H$11,MATCH(A24&"-"&B24,'④回収ファイル一覧'!$K$4:$K$11,0)),"")} | L24: {=IFERROR(INDEX('④回収ファイル一覧'!$I$4:$I$11,MATCH(A24&"-"&B24,'④回収ファイル一覧'!$K$4:$K$11,0)),"")} | M24: {=IFERROR(INDEX('④回収ファイル一覧'!$J$4:$J$11,MATCH(A24&"-"&B24,'④回収ファイル一覧'!$K$4:$K$11,0)),"")}
A25: 1 | B25: 3 | C25: A6 | D25: 立って戻る | E25: 反応しない | G25: 10 | J25: {=IFERROR(INDEX('④回収ファイル一覧'!$G$4:$G$11,MATCH(A25&"-"&B25,'④回収ファイル一覧'!$K$4:$K$11,0)),"")} | K25: {=IFERROR(INDEX('④回収ファイル一覧'!$H$4:$H$11,MATCH(A25&"-"&B25,'④回収ファイル一覧'!$K$4:$K$11,0)),"")} | L25: {=IFERROR(INDEX('④回収ファイル一覧'!$I$4:$I$11,MATCH(A25&"-"&B25,'④回収ファイル一覧'!$K$4:$K$11,0)),"")} | M25: {=IFERROR(INDEX('④回収ファイル一覧'!$J$4:$J$11,MATCH(A25&"-"&B25,'④回収ファイル一覧'!$K$4:$K$11,0)),"")}
A26: 1 | B26: 3 | C26: B1 | D26: 声を出して笑う | E26: 反応する | G26: 6 | J26: {=IFERROR(INDEX('④回収ファイル一覧'!$G$4:$G$11,MATCH(A26&"-"&B26,'④回収ファイル一覧'!$K$4:$K$11,0)),"")} | K26: {=IFERROR(INDEX('④回収ファイル一覧'!$H$4:$H$11,MATCH(A26&"-"&B26,'④回収ファイル一覧'!$K$4:$K$11,0)),"")} | L26: {=IFERROR(INDEX('④回収ファイル一覧'!$I$4:$I$11,MATCH(A26&"-"&B26,'④回収ファイル一覧'!$K$4:$K$11,0)),"")} | M26: {=IFERROR(INDEX('④回収ファイル一覧'!$J$4:$J$11,MATCH(A26&"-"&B26,'④回収ファイル一覧'!$K$4:$K$11,0)),"")}
A27: 1 | B27: 3 | C27: B2 | D27: 驚く | E27: 反応する | G27: 5 | J27: {=IFERROR(INDEX('④回収ファイル一覧'!$G$4:$G$11,MATCH(A27&"-"&B27,'④回収ファイル一覧'!$K$4:$K$11,0)),"")} | K27: {=IFERROR(INDEX('④回収ファイル一覧'!$H$4:$H$11,MATCH(A27&"-"&B27,'④回収ファイル一覧'!$K$4:$K$11,0)),"")} | L27: {=IFERROR(INDEX('④回収ファイル一覧'!$I$4:$I$11,MATCH(A27&"-"&B27,'④回収ファイル一覧'!$K$4:$K$11,0)),"")} | M27: {=IFERROR(INDEX('④回収ファイル一覧'!$J$4:$J$11,MATCH(A27&"-"&B27,'④回収ファイル一覧'!$K$4:$K$11,0)),"")}
A28: 1 | B28: 3 | C28: B3 | D28: 怒る | E28: 反応する | G28: 3 | J28: {=IFERROR(INDEX('④回収ファイル一覧'!$G$4:$G$11,MATCH(A28&"-"&B28,'④回収ファイル一覧'!$K$4:$K$11,0)),"")} | K28: {=IFERROR(INDEX('④回収ファイル一覧'!$H$4:$H$11,MATCH(A28&"-"&B28,'④回収ファイル一覧'!$K$4:$K$11,0)),"")} | L28: {=IFERROR(INDEX('④回収ファイル一覧'!$I$4:$I$11,MATCH(A28&"-"&B28,'④回収ファイル一覧'!$K$4:$K$11,0)),"")} | M28: {=IFERROR(INDEX('④回収ファイル一覧'!$J$4:$J$11,MATCH(A28&"-"&B28,'④回収ファイル一覧'!$K$4:$K$11,0)),"")}
A29: 1 | B29: 3 | C29: B4 | D29: 静かに笑う（声量そのまま） | E29: 反応する | G29: 2 | J29: {=IFERROR(INDEX('④回収ファイル一覧'!$G$4:$G$11,MATCH(A29&"-"&B29,'④回収ファイル一覧'!$K$4:$K$11,0)),"")} | K29: {=IFERROR(INDEX('④回収ファイル一覧'!$H$4:$H$11,MATCH(A29&"-"&B29,'④回収ファイル一覧'!$K$4:$K$11,0)),"")} | L29: {=IFERROR(INDEX('④回収ファイル一覧'!$I$4:$I$11,MATCH(A29&"-"&B29,'④回収ファイル一覧'!$K$4:$K$11,0)),"")} | M29: {=IFERROR(INDEX('④回収ファイル一覧'!$J$4:$J$11,MATCH(A29&"-"&B29,'④回収ファイル一覧'!$K$4:$K$11,0)),"")}
A30: 1 | B30: 3 | C30: B5 | D30: ほめ言葉（ふだんの声） | E30: 反応する | G30: 4 | J30: {=IFERROR(INDEX('④回収ファイル一覧'!$G$4:$G$11,MATCH(A30&"-"&B30,'④回収ファイル一覧'!$K$4:$K$11,0)),"")} | K30: {=IFERROR(INDEX('④回収ファイル一覧'!$H$4:$H$11,MATCH(A30&"-"&B30,'④回収ファイル一覧'!$K$4:$K$11,0)),"")} | L30: {=IFERROR(INDEX('④回収ファイル一覧'!$I$4:$I$11,MATCH(A30&"-"&B30,'④回収ファイル一覧'!$K$4:$K$11,0)),"")} | M30: {=IFERROR(INDEX('④回収ファイル一覧'!$J$4:$J$11,MATCH(A30&"-"&B30,'④回収ファイル一覧'!$K$4:$K$11,0)),"")}
A31: 1 | B31: 3 | C31: B6 | D31: 感極まる | E31: 反応する | G31: 4 | J31: {=IFERROR(INDEX('④回収ファイル一覧'!$G$4:$G$11,MATCH(A31&"-"&B31,'④回収ファイル一覧'!$K$4:$K$11,0)),"")} | K31: {=IFERROR(INDEX('④回収ファイル一覧'!$H$4:$H$11,MATCH(A31&"-"&B31,'④回収ファイル一覧'!$K$4:$K$11,0)),"")} | L31: {=IFERROR(INDEX('④回収ファイル一覧'!$I$4:$I$11,MATCH(A31&"-"&B31,'④回収ファイル一覧'!$K$4:$K$11,0)),"")} | M31: {=IFERROR(INDEX('④回収ファイル一覧'!$J$4:$J$11,MATCH(A31&"-"&B31,'④回収ファイル一覧'!$K$4:$K$11,0)),"")}
A32: 1 | B32: 3 | C32: C1 | D32: 咳・くしゃみ・あくび | E32: 記録のみ | G32: 2 | I32: 咳、くしゃみ | J32: {=IFERROR(INDEX('④回収ファイル一覧'!$G$4:$G$11,MATCH(A32&"-"&B32,'④回収ファイル一覧'!$K$4:$K$11,0)),"")} | K32: {=IFERROR(INDEX('④回収ファイル一覧'!$H$4:$H$11,MATCH(A32&"-"&B32,'④回収ファイル一覧'!$K$4:$K$11,0)),"")} | L32: {=IFERROR(INDEX('④回収ファイル一覧'!$I$4:$I$11,MATCH(A32&"-"&B32,'④回収ファイル一覧'!$K$4:$K$11,0)),"")} | M32: {=IFERROR(INDEX('④回収ファイル一覧'!$J$4:$J$11,MATCH(A32&"-"&B32,'④回収ファイル一覧'!$K$4:$K$11,0)),"")}
A33: 1 | B33: 3 | C33: C2 | D33: 笑い続ける30秒 | E33: 2回以上反応が正解 | G33: 5 | J33: {=IFERROR(INDEX('④回収ファイル一覧'!$G$4:$G$11,MATCH(A33&"-"&B33,'④回収ファイル一覧'!$K$4:$K$11,0)),"")} | K33: {=IFERROR(INDEX('④回収ファイル一覧'!$H$4:$H$11,MATCH(A33&"-"&B33,'④回収ファイル一覧'!$K$4:$K$11,0)),"")} | L33: {=IFERROR(INDEX('④回収ファイル一覧'!$I$4:$I$11,MATCH(A33&"-"&B33,'④回収ファイル一覧'!$K$4:$K$11,0)),"")} | M33: {=IFERROR(INDEX('④回収ファイル一覧'!$J$4:$J$11,MATCH(A33&"-"&B33,'④回収ファイル一覧'!$K$4:$K$11,0)),"")}
A34: 1 | B34: 3 | C34: C3 | D34: 家族側が大声（テスター無言） | E34: 記録のみ | G34: 3 | J34: {=IFERROR(INDEX('④回収ファイル一覧'!$G$4:$G$11,MATCH(A34&"-"&B34,'④回収ファイル一覧'!$K$4:$K$11,0)),"")} | K34: {=IFERROR(INDEX('④回収ファイル一覧'!$H$4:$H$11,MATCH(A34&"-"&B34,'④回収ファイル一覧'!$K$4:$K$11,0)),"")} | L34: {=IFERROR(INDEX('④回収ファイル一覧'!$I$4:$I$11,MATCH(A34&"-"&B34,'④回収ファイル一覧'!$K$4:$K$11,0)),"")} | M34: {=IFERROR(INDEX('④回収ファイル一覧'!$J$4:$J$11,MATCH(A34&"-"&B34,'④回収ファイル一覧'!$K$4:$K$11,0)),"")}
A35: 2 | B35: 1 | C35: A1 | D35: 静かにする | E35: 反応しない | J35: {=IFERROR(INDEX('④回収ファイル一覧'!$G$4:$G$11,MATCH(A35&"-"&B35,'④回収ファイル一覧'!$K$4:$K$11,0)),"")} | K35: {=IFERROR(INDEX('④回収ファイル一覧'!$H$4:$H$11,MATCH(A35&"-"&B35,'④回収ファイル一覧'!$K$4:$K$11,0)),"")} | L35: {=IFERROR(INDEX('④回収ファイル一覧'!$I$4:$I$11,MATCH(A35&"-"&B35,'④回収ファイル一覧'!$K$4:$K$11,0)),"")} | M35: {=IFERROR(INDEX('④回収ファイル一覧'!$J$4:$J$11,MATCH(A35&"-"&B35,'④回収ファイル一覧'!$K$4:$K$11,0)),"")}
A36: 2 | B36: 1 | C36: A2 | D36: ふつうの雑談（10分） | E36: 反応しない | J36: {=IFERROR(INDEX('④回収ファイル一覧'!$G$4:$G$11,MATCH(A36&"-"&B36,'④回収ファイル一覧'!$K$4:$K$11,0)),"")} | K36: {=IFERROR(INDEX('④回収ファイル一覧'!$H$4:$H$11,MATCH(A36&"-"&B36,'④回収ファイル一覧'!$K$4:$K$11,0)),"")} | L36: {=IFERROR(INDEX('④回収ファイル一覧'!$I$4:$I$11,MATCH(A36&"-"&B36,'④回収ファイル一覧'!$K$4:$K$11,0)),"")} | M36: {=IFERROR(INDEX('④回収ファイル一覧'!$J$4:$J$11,MATCH(A36&"-"&B36,'④回収ファイル一覧'!$K$4:$K$11,0)),"")}
A37: 2 | B37: 1 | C37: A3 | D37: 本を読む | E37: 反応しない | J37: {=IFERROR(INDEX('④回収ファイル一覧'!$G$4:$G$11,MATCH(A37&"-"&B37,'④回収ファイル一覧'!$K$4:$K$11,0)),"")} | K37: {=IFERROR(INDEX('④回収ファイル一覧'!$H$4:$H$11,MATCH(A37&"-"&B37,'④回収ファイル一覧'!$K$4:$K$11,0)),"")} | L37: {=IFERROR(INDEX('④回収ファイル一覧'!$I$4:$I$11,MATCH(A37&"-"&B37,'④回収ファイル一覧'!$K$4:$K$11,0)),"")} | M37: {=IFERROR(INDEX('④回収ファイル一覧'!$J$4:$J$11,MATCH(A37&"-"&B37,'④回収ファイル一覧'!$K$4:$K$11,0)),"")}
A38: 2 | B38: 1 | C38: A4 | D38: 生活音を出す | E38: 反応しない | J38: {=IFERROR(INDEX('④回収ファイル一覧'!$G$4:$G$11,MATCH(A38&"-"&B38,'④回収ファイル一覧'!$K$4:$K$11,0)),"")} | K38: {=IFERROR(INDEX('④回収ファイル一覧'!$H$4:$H$11,MATCH(A38&"-"&B38,'④回収ファイル一覧'!$K$4:$K$11,0)),"")} | L38: {=IFERROR(INDEX('④回収ファイル一覧'!$I$4:$I$11,MATCH(A38&"-"&B38,'④回収ファイル一覧'!$K$4:$K$11,0)),"")} | M38: {=IFERROR(INDEX('④回収ファイル一覧'!$J$4:$J$11,MATCH(A38&"-"&B38,'④回収ファイル一覧'!$K$4:$K$11,0)),"")}
A39: 2 | B39: 1 | C39: A5 | D39: 最初のあいさつ（かけ直し） | E39: 反応しない | J39: {=IFERROR(INDEX('④回収ファイル一覧'!$G$4:$G$11,MATCH(A39&"-"&B39,'④回収ファイル一覧'!$K$4:$K$11,0)),"")} | K39: {=IFERROR(INDEX('④回収ファイル一覧'!$H$4:$H$11,MATCH(A39&"-"&B39,'④回収ファイル一覧'!$K$4:$K$11,0)),"")} | L39: {=IFERROR(INDEX('④回収ファイル一覧'!$I$4:$I$11,MATCH(A39&"-"&B39,'④回収ファイル一覧'!$K$4:$K$11,0)),"")} | M39: {=IFERROR(INDEX('④回収ファイル一覧'!$J$4:$J$11,MATCH(A39&"-"&B39,'④回収ファイル一覧'!$K$4:$K$11,0)),"")}
A40: 2 | B40: 1 | C40: A6 | D40: 立って戻る | E40: 反応しない | J40: {=IFERROR(INDEX('④回収ファイル一覧'!$G$4:$G$11,MATCH(A40&"-"&B40,'④回収ファイル一覧'!$K$4:$K$11,0)),"")} | K40: {=IFERROR(INDEX('④回収ファイル一覧'!$H$4:$H$11,MATCH(A40&"-"&B40,'④回収ファイル一覧'!$K$4:$K$11,0)),"")} | L40: {=IFERROR(INDEX('④回収ファイル一覧'!$I$4:$I$11,MATCH(A40&"-"&B40,'④回収ファイル一覧'!$K$4:$K$11,0)),"")} | M40: {=IFERROR(INDEX('④回収ファイル一覧'!$J$4:$J$11,MATCH(A40&"-"&B40,'④回収ファイル一覧'!$K$4:$K$11,0)),"")}
A41: 2 | B41: 1 | C41: B1 | D41: 声を出して笑う | E41: 反応する | J41: {=IFERROR(INDEX('④回収ファイル一覧'!$G$4:$G$11,MATCH(A41&"-"&B41,'④回収ファイル一覧'!$K$4:$K$11,0)),"")} | K41: {=IFERROR(INDEX('④回収ファイル一覧'!$H$4:$H$11,MATCH(A41&"-"&B41,'④回収ファイル一覧'!$K$4:$K$11,0)),"")} | L41: {=IFERROR(INDEX('④回収ファイル一覧'!$I$4:$I$11,MATCH(A41&"-"&B41,'④回収ファイル一覧'!$K$4:$K$11,0)),"")} | M41: {=IFERROR(INDEX('④回収ファイル一覧'!$J$4:$J$11,MATCH(A41&"-"&B41,'④回収ファイル一覧'!$K$4:$K$11,0)),"")}
...

Sheet ④回収ファイル一覧
A1: チェックリスト — 回収ファイル一覧
A3: ラウンド | B3: セッション(Day) | C3: 実施日 | D3: 記録ファイル名 | E3: 画面録画ファイル名 | F3: 開発チームへ送付 | G3: 高齢者役_環境（場所・部屋） | H3: 高齢者役_マイク／イヤホン機種 | I3: 家族役_環境（場所・部屋） | J3: 家族役_マイク／イヤホン機種 | K3: キー（自動・触らないで）
A4: 1 | B4: 1 | G4: 例: 自宅リビング（静か） | H4: 例: PC内蔵マイク | I4: 例: 会社の会議室 | J4: 例: AirPods Pro | K4: =A4&"-"&B4
A5: 1 | B5: 2 | I5: =A5&"-"&B5 | K5: =A5&"-"&B5
A6: 1 | B6: 3 | I6: =A6&"-"&B6 | K6: =A6&"-"&B6
A7: 2 | B7: 1 | I7: =A7&"-"&B7 | K7: =A7&"-"&B7
A8: 2 | B8: 2 | I8: =A8&"-"&B8 | K8: =A8&"-"&B8
A9: 2 | B9: 3 | I9: =A9&"-"&B9 | K9: =A9&"-"&B9

Sheet ⑤サマリー
A1: チェックリスト — サマリー（自動集計・見るだけ）
A3: 番号 | B3: 場面 | C3: 正解 | D3: Round1 | H3: Round2
D4: 実施済み数 | E4: 反応回数の合計 | F4: ◯の数 | G4: ×の数 | H4: 実施済み数 | I4: 反応回数の合計 | J4: ◯の数 | K4: ×の数
A5: A1 | B5: 静かにする | C5: 反応しない | D5: =COUNTIFS('③実施記録'!A:A,1,'③実施記録'!C:C,"A1",'③実施記録'!F:F,"<>") | E5: =SUMIFS('③実施記録'!G:G,'③実施記録'!A:A,1,'③実施記録'!C:C,"A1") | F5: =COUNTIFS('③実施記録'!A:A,1,'③実施記録'!C:C,"A1",'③実施記録'!H:H,"◯") | G5: =COUNTIFS('③実施記録'!A:A,1,'③実施記録'!C:C,"A1",'③実施記録'!H:H,"×") | H5: =COUNTIFS('③実施記録'!A:A,2,'③実施記録'!C:C,"A1",'③実施記録'!F:F,"<>") | I5: =SUMIFS('③実施記録'!G:G,'③実施記録'!A:A,2,'③実施記録'!C:C,"A1") | J5: =COUNTIFS('③実施記録'!A:A,2,'③実施記録'!C:C,"A1",'③実施記録'!H:H,"◯") | K5: =COUNTIFS('③実施記録'!A:A,2,'③実施記録'!C:C,"A1",'③実施記録'!H:H,"×")
A6: A2 | B6: ふつうの雑談（10分） | C6: 反応しない | D6: =COUNTIFS('③実施記録'!A:A,1,'③実施記録'!C:C,"A2",'③実施記録'!F:F,"<>") | E6: =SUMIFS('③実施記録'!G:G,'③実施記録'!A:A,1,'③実施記録'!C:C,"A2") | F6: =COUNTIFS('③実施記録'!A:A,1,'③実施記録'!C:C,"A2",'③実施記録'!H:H,"◯") | G6: =COUNTIFS('③実施記録'!A:A,1,'③実施記録'!C:C,"A2",'③実施記録'!H:H,"×") | H6: =COUNTIFS('③実施記録'!A:A,2,'③実施記録'!C:C,"A2",'③実施記録'!F:F,"<>") | I6: =SUMIFS('③実施記録'!G:G,'③実施記録'!A:A,2,'③実施記録'!C:C,"A2") | J6: =COUNTIFS('③実施記録'!A:A,2,'③実施記録'!C:C,"A2",'③実施記録'!H:H,"◯") | K6: =COUNTIFS('③実施記録'!A:A,2,'③実施記録'!C:C,"A2",'③実施記録'!H:H,"×")
A7: A3 | B7: 本を読む | C7: 反応しない | D7: =COUNTIFS('③実施記録'!A:A,1,'③実施記録'!C:C,"A3",'③実施記録'!F:F,"<>") | E7: =SUMIFS('③実施記録'!G:G,'③実施記録'!A:A,1,'③実施記録'!C:C,"A3") | F7: =COUNTIFS('③実施記録'!A:A,1,'③実施記録'!C:C,"A3",'③実施記録'!H:H,"◯") | G7: =COUNTIFS('③実施記録'!A:A,1,'③実施記録'!C:C,"A3",'③実施記録'!H:H,"×") | H7: =COUNTIFS('③実施記録'!A:A,2,'③実施記録'!C:C,"A3",'③実施記録'!F:F,"<>") | I7: =SUMIFS('③実施記録'!G:G,'③実施記録'!A:A,2,'③実施記録'!C:C,"A3") | J7: =COUNTIFS('③実施記録'!A:A,2,'③実施記録'!C:C,"A3",'③実施記録'!H:H,"◯") | K7: =COUNTIFS('③実施記録'!A:A,2,'③実施記録'!C:C,"A3",'③実施記録'!H:H,"×")
A8: A4 | B8: 生活音を出す | C8: 反応しない | D8: =COUNTIFS('③実施記録'!A:A,1,'③実施記録'!C:C,"A4",'③実施記録'!F:F,"<>") | E8: =SUMIFS('③実施記録'!G:G,'③実施記録'!A:A,1,'③実施記録'!C:C,"A4") | F8: =COUNTIFS('③実施記録'!A:A,1,'③実施記録'!C:C,"A4",'③実施記録'!H:H,"◯") | G8: =COUNTIFS('③実施記録'!A:A,1,'③実施記録'!C:C,"A4",'③実施記録'!H:H,"×") | H8: =COUNTIFS('③実施記録'!A:A,2,'③実施記録'!C:C,"A4",'③実施記録'!F:F,"<>") | I8: =SUMIFS('③実施記録'!G:G,'③実施記録'!A:A,2,'③実施記録'!C:C,"A4") | J8: =COUNTIFS('③実施記録'!A:A,2,'③実施記録'!C:C,"A4",'③実施記録'!H:H,"◯") | K8: =COUNTIFS('③実施記録'!A:A,2,'③実施記録'!C:C,"A4",'③実施記録'!H:H,"×")
A9: A5 | B9: 最初のあいさつ（かけ直し） | C9: 反応しない | D9: =COUNTIFS('③実施記録'!A:A,1,'③実施記録'!C:C,"A5",'③実施記録'!F:F,"<>") | E9: =SUMIFS('③実施記録'!G:G,'③実施記録'!A:A,1,'③実施記録'!C:C,"A5") | F9: =COUNTIFS('③実施記録'!A:A,1,'③実施記録'!C:C,"A5",'③実施記録'!H:H,"◯") | G9: =COUNTIFS('③実施記録'!A:A,1,'③実施記録'!C:C,"A5",'③実施記録'!H:H,"×") | H9: =COUNTIFS('③実施記録'!A:A,2,'③実施記録'!C:C,"A5",'③実施記録'!F:F,"<>") | I9: =SUMIFS('③実施記録'!G:G,'③実施記録'!A:A,2,'③実施記録'!C:C,"A5") | J9: =COUNTIFS('③実施記録'!A:A,2,'③実施記録'!C:C,"A5",'③実施記録'!H:H,"◯") | K9: =COUNTIFS('③実施記録'!A:A,2,'③実施記録'!C:C,"A5",'③実施記録'!H:H,"×")
A10: A6 | B10: 立って戻る | C10: 反応しない | D10: =COUNTIFS('③実施記録'!A:A,1,'③実施記録'!C:C,"A6",'③実施記録'!F:F,"<>") | E10: =SUMIFS('③実施記録'!G:G,'③実施記録'!A:A,1,'③実施記録'!C:C,"A6") | F10: =COUNTIFS('③実施記録'!A:A,1,'③実施記録'!C:C,"A6",'③実施記録'!H:H,"◯") | G10: =COUNTIFS('③実施記録'!A:A,1,'③実施記録'!C:C,"A6",'③実施記録'!H:H,"×") | H10: =COUNTIFS('③実施記録'!A:A,2,'③実施記録'!C:C,"A6",'③実施記録'!F:F,"<>") | I10: =SUMIFS('③実施記録'!G:G,'③実施記録'!A:A,2,'③実施記録'!C:C,"A6") | J10: =COUNTIFS('③実施記録'!A:A,2,'③実施記録'!C:C,"A6",'③実施記録'!H:H,"◯") | K10: =COUNTIFS('③実施記録'!A:A,2,'③実施記録'!C:C,"A6",'③実施記録'!H:H,"×")
A11: B1 | B11: 声を出して笑う | C11: 反応する | D11: =COUNTIFS('③実施記録'!A:A,1,'③実施記録'!C:C,"B1",'③実施記録'!F:F,"<>") | E11: =SUMIFS('③実施記録'!G:G,'③実施記録'!A:A,1,'③実施記録'!C:C,"B1") | F11: =COUNTIFS('③実施記録'!A:A,1,'③実施記録'!C:C,"B1",'③実施記録'!H:H,"◯") | G11: =COUNTIFS('③実施記録'!A:A,1,'③実施記録'!C:C,"B1",'③実施記録'!H:H,"×") | H11: =COUNTIFS('③実施記録'!A:A,2,'③実施記録'!C:C,"B1",'③実施記録'!F:F,"<>") | I11: =SUMIFS('③実施記録'!G:G,'③実施記録'!A:A,2,'③実施記録'!C:C,"B1") | J11: =COUNTIFS('③実施記録'!A:A,2,'③実施記録'!C:C,"B1",'③実施記録'!H:H,"◯") | K11: =COUNTIFS('③実施記録'!A:A,2,'③実施記録'!C:C,"B1",'③実施記録'!H:H,"×")
A12: B2 | B12: 驚く | C12: 反応する | D12: =COUNTIFS('③実施記録'!A:A,1,'③実施記録'!C:C,"B2",'③実施記録'!F:F,"<>") | E12: =SUMIFS('③実施記録'!G:G,'③実施記録'!A:A,1,'③実施記録'!C:C,"B2") | F12: =COUNTIFS('③実施記録'!A:A,1,'③実施記録'!C:C,"B2",'③実施記録'!H:H,"◯") | G12: =COUNTIFS('③実施記録'!A:A,1,'③実施記録'!C:C,"B2",'③実施記録'!H:H,"×") | H12: =COUNTIFS('③実施記録'!A:A,2,'③実施記録'!C:C,"B2",'③実施記録'!F:F,"<>") | I12: =SUMIFS('③実施記録'!G:G,'③実施記録'!A:A,2,'③実施記録'!C:C,"B2") | J12: =COUNTIFS('③実施記録'!A:A,2,'③実施記録'!C:C,"B2",'③実施記録'!H:H,"◯") | K12: =COUNTIFS('③実施記録'!A:A,2,'③実施記録'!C:C,"B2",'③実施記録'!H:H,"×")
A13: B3 | B13: 怒る | C13: 反応する | D13: =COUNTIFS('③実施記録'!A:A,1,'③実施記録'!C:C,"B3",'③実施記録'!F:F,"<>") | E13: =SUMIFS('③実施記録'!G:G,'③実施記録'!A:A,1,'③実施記録'!C:C,"B3") | F13: =COUNTIFS('③実施記録'!A:A,1,'③実施記録'!C:C,"B3",'③実施記録'!H:H,"◯") | G13: =COUNTIFS('③実施記録'!A:A,1,'③実施記録'!C:C,"B3",'③実施記録'!H:H,"×") | H13: =COUNTIFS('③実施記録'!A:A,2,'③実施記録'!C:C,"B3",'③実施記録'!F:F,"<>") | I13: =SUMIFS('③実施記録'!G:G,'③実施記録'!A:A,2,'③実施記録'!C:C,"B3") | J13: =COUNTIFS('③実施記録'!A:A,2,'③実施記録'!C:C,"B3",'③実施記録'!H:H,"◯") | K13: =COUNTIFS('③実施記録'!A:A,2,'③実施記録'!C:C,"B3",'③実施記録'!H:H,"×")
A14: B4 | B14: 静かに笑う（声量そのまま） | C14: 反応する | D14: =COUNTIFS('③実施記録'!A:A,1,'③実施記録'!C:C,"B4",'③実施記録'!F:F,"<>") | E14: =SUMIFS('③実施記録'!G:G,'③実施記録'!A:A,1,'③実施記録'!C:C,"B4") | F14: =COUNTIFS('③実施記録'!A:A,1,'③実施記録'!C:C,"B4",'③実施記録'!H:H,"◯") | G14: =COUNTIFS('③実施記録'!A:A,1,'③実施記録'!C:C,"B4",'③実施記録'!H:H,"×") | H14: =COUNTIFS('③実施記録'!A:A,2,'③実施記録'!C:C,"B4",'③実施記録'!F:F,"<>") | I14: =SUMIFS('③実施記録'!G:G,'③実施記録'!A:A,2,'③実施記録'!C:C,"B4") | J14: =COUNTIFS('③実施記録'!A:A,2,'③実施記録'!C:C,"B4",'③実施記録'!H:H,"◯") | K14: =COUNTIFS('③実施記録'!A:A,2,'③実施記録'!C:C,"B4",'③実施記録'!H:H,"×")
A15: B5 | B15: ほめ言葉（ふだんの声） | C15: 反応する | D15: =COUNTIFS('③実施記録'!A:A,1,'③実施記録'!C:C,"B5",'③実施記録'!F:F,"<>") | E15: =SUMIFS('③実施記録'!G:G,'③実施記録'!A:A,1,'③実施記録'!C:C,"B5") | F15: =COUNTIFS('③実施記録'!A:A,1,'③実施記録'!C:C,"B5",'③実施記録'!H:H,"◯") | G15: =COUNTIFS('③実施記録'!A:A,1,'③実施記録'!C:C,"B5",'③実施記録'!H:H,"×") | H15: =COUNTIFS('③実施記録'!A:A,2,'③実施記録'!C:C,"B5",'③実施記録'!F:F,"<>") | I15: =SUMIFS('③実施記録'!G:G,'③実施記録'!A:A,2,'③実施記録'!C:C,"B5") | J15: =COUNTIFS('③実施記録'!A:A,2,'③実施記録'!C:C,"B5",'③実施記録'!H:H,"◯") | K15: =COUNTIFS('③実施記録'!A:A,2,'③実施記録'!C:C,"B5",'③実施記録'!H:H,"×")
A16: B6 | B16: 感極まる | C16: 反応する | D16: =COUNTIFS('③実施記録'!A:A,1,'③実施記録'!C:C,"B6",'③実施記録'!F:F,"<>") | E16: =SUMIFS('③実施記録'!G:G,'③実施記録'!A:A,1,'③実施記録'!C:C,"B6") | F16: =COUNTIFS('③実施記録'!A:A,1,'③実施記録'!C:C,"B6",'③実施記録'!H:H,"◯") | G16: =COUNTIFS('③実施記録'!A:A,1,'③実施記録'!C:C,"B6",'③実施記録'!H:H,"×") | H16: =COUNTIFS('③実施記録'!A:A,2,'③実施記録'!C:C,"B6",'③実施記録'!F:F,"<>") | I16: =SUMIFS('③実施記録'!G:G,'③実施記録'!A:A,2,'③実施記録'!C:C,"B6") | J16: =COUNTIFS('③実施記録'!A:A,2,'③実施記録'!C:C,"B6",'③実施記録'!H:H,"◯") | K16: =COUNTIFS('③実施記録'!A:A,2,'③実施記録'!C:C,"B6",'③実施記録'!H:H,"×")
A17: C1 | B17: 咳・くしゃみ・あくび | C17: 記録のみ | D17: =COUNTIFS('③実施記録'!A:A,1,'③実施記録'!C:C,"C1",'③実施記録'!F:F,"<>") | E17: =SUMIFS('③実施記録'!G:G,'③実施記録'!A:A,1,'③実施記録'!C:C,"C1") | F17: =COUNTIFS('③実施記録'!A:A,1,'③実施記録'!C:C,"C1",'③実施記録'!H:H,"◯") | G17: =COUNTIFS('③実施記録'!A:A,1,'③実施記録'!C:C,"C1",'③実施記録'!H:H,"×") | H17: =COUNTIFS('③実施記録'!A:A,2,'③実施記録'!C:C,"C1",'③実施記録'!F:F,"<>") | I17: =SUMIFS('③実施記録'!G:G,'③実施記録'!A:A,2,'③実施記録'!C:C,"C1") | J17: =COUNTIFS('③実施記録'!A:A,2,'③実施記録'!C:C,"C1",'③実施記録'!H:H,"◯") | K17: =COUNTIFS('③実施記録'!A:A,2,'③実施記録'!C:C,"C1",'③実施記録'!H:H,"×")
A18: C2 | B18: 笑い続ける30秒 | C18: 2回以上反応が正解 | D18: =COUNTIFS('③実施記録'!A:A,1,'③実施記録'!C:C,"C2",'③実施記録'!F:F,"<>") | E18: =SUMIFS('③実施記録'!G:G,'③実施記録'!A:A,1,'③実施記録'!C:C,"C2") | F18: =COUNTIFS('③実施記録'!A:A,1,'③実施記録'!C:C,"C2",'③実施記録'!H:H,"◯") | G18: =COUNTIFS('③実施記録'!A:A,1,'③実施記録'!C:C,"C2",'③実施記録'!H:H,"×") | H18: =COUNTIFS('③実施記録'!A:A,2,'③実施記録'!C:C,"C2",'③実施記録'!F:F,"<>") | I18: =SUMIFS('③実施記録'!G:G,'③実施記録'!A:A,2,'③実施記録'!C:C,"C2") | J18: =COUNTIFS('③実施記録'!A:A,2,'③実施記録'!C:C,"C2",'③実施記録'!H:H,"◯") | K18: =COUNTIFS('③実施記録'!A:A,2,'③実施記録'!C:C,"C2",'③実施記録'!H:H,"×")
A19: C3 | B19: 家族側が大声（テスター無言） | C19: 記録のみ | D19: =COUNTIFS('③実施記録'!A:A,1,'③実施記録'!C:C,"C3",'③実施記録'!F:F,"<>") | E19: =SUMIFS('③実施記録'!G:G,'③実施記録'!A:A,1,'③実施記録'!C:C,"C3") | F19: =COUNTIFS('③実施記録'!A:A,1,'③実施記録'!C:C,"C3",'③実施記録'!H:H,"◯") | G19: =COUNTIFS('③実施記録'!A:A,1,'③実施記録'!C:C,"C3",'③実施記録'!H:H,"×") | H19: =COUNTIFS('③実施記録'!A:A,2,'③実施記録'!C:C,"C3",'③実施記録'!F:F,"<>") | I19: =SUMIFS('③実施記録'!G:G,'③実施記録'!A:A,2,'③実施記録'!C:C,"C3") | J19: =COUNTIFS('③実施記録'!A:A,2,'③実施記録'!C:C,"C3",'③実施記録'!H:H,"◯") | K19: =COUNTIFS('③実施記録'!A:A,2,'③実施記録'!C:C,"C3",'③実施記録'!H:H,"×")
A21: ※ この表は自動計算です。手で書き換えないでください。
